Traceback (most recent call last):
  File "/opt/hostedtoolcache/Python/3.8.18/x64/lib/python3.8/site-packages/jupyter_cache/executors/utils.py", line 58, in single_nb_execution
    executenb(
  File "/opt/hostedtoolcache/Python/3.8.18/x64/lib/python3.8/site-packages/nbclient/client.py", line 1305, in execute
    return NotebookClient(nb=nb, resources=resources, km=km, **kwargs).execute()
  File "/opt/hostedtoolcache/Python/3.8.18/x64/lib/python3.8/site-packages/jupyter_core/utils/__init__.py", line 165, in wrapped
    return loop.run_until_complete(inner)
  File "/opt/hostedtoolcache/Python/3.8.18/x64/lib/python3.8/asyncio/base_events.py", line 616, in run_until_complete
    return future.result()
  File "/opt/hostedtoolcache/Python/3.8.18/x64/lib/python3.8/site-packages/nbclient/client.py", line 705, in async_execute
    await self.async_execute_cell(
  File "/opt/hostedtoolcache/Python/3.8.18/x64/lib/python3.8/site-packages/nbclient/client.py", line 1058, in async_execute_cell
    await self._check_raise_for_error(cell, cell_index, exec_reply)
  File "/opt/hostedtoolcache/Python/3.8.18/x64/lib/python3.8/site-packages/nbclient/client.py", line 914, in _check_raise_for_error
    raise CellExecutionError.from_cell_and_msg(cell, exec_reply_content)
nbclient.exceptions.CellExecutionError: An error occurred while executing the following cell:
------------------
x0 = [1, 1.27e-6, 0]

t = numpy.linspace(0, 150, 100).astype('float64')

ode.initial_values = (x0, t[0])

solution = ode.integrate(t[1::])

theta = [0.2, 0.2]

targetState = ['R']

targetStateIndex = numpy.array(ode.get_state_index(targetState))

y = solution[1::,targetStateIndex] + numpy.random.normal(0,0.01, (len(solution[1::,targetStateIndex]), 1))

yObv = y.copy()

objSIR = NormalLoss(theta, ode, x0, t[0], t[1::], y, targetState)

boxBounds = [(1e-8, 2.0), (1e-8, 2.0)]

boxBoundsArray = numpy.array(boxBounds)

xhat = objSIR.fit(theta, lb=boxBoundsArray[:,0], ub=boxBoundsArray[:,1])


------------------


[0;31m---------------------------------------------------------------------------[0m
[0;31mNameError[0m                                 Traceback (most recent call last)
Cell [0;32mIn[1], line 3[0m
[1;32m      1[0m x0 [38;5;241m=[39m [[38;5;241m1[39m, [38;5;241m1.27e-6[39m, [38;5;241m0[39m]
[0;32m----> 3[0m t [38;5;241m=[39m [43mnumpy[49m[38;5;241m.[39mlinspace([38;5;241m0[39m, [38;5;241m150[39m, [38;5;241m100[39m)[38;5;241m.[39mastype([38;5;124m'[39m[38;5;124mfloat64[39m[38;5;124m'[39m)
[1;32m      5[0m ode[38;5;241m.[39minitial_values [38;5;241m=[39m (x0, t[[38;5;241m0[39m])
[1;32m      7[0m solution [38;5;241m=[39m ode[38;5;241m.[39mintegrate(t[[38;5;241m1[39m::])

[0;31mNameError[0m: name 'numpy' is not defined

